2025-03-18 14:33:45,680 INFO    MainThread:22024 [wandb_setup.py:_flush():67] Current SDK version is 0.19.8
2025-03-18 14:33:45,680 INFO    MainThread:22024 [wandb_setup.py:_flush():67] Configure stats pid to 22024
2025-03-18 14:33:45,680 INFO    MainThread:22024 [wandb_setup.py:_flush():67] Loading settings from C:\Users\Colton\.config\wandb\settings
2025-03-18 14:33:45,680 INFO    MainThread:22024 [wandb_setup.py:_flush():67] Loading settings from C:\Users\Colton\Documents\GitHub\cs260r-assignment-2025winter\mini_project\wandb\settings
2025-03-18 14:33:45,680 INFO    MainThread:22024 [wandb_setup.py:_flush():67] Loading settings from environment variables
2025-03-18 14:33:45,680 INFO    MainThread:22024 [wandb_init.py:setup_run_log_directory():647] Logging user logs to runs\sac_metadrive\sac_metadrive_2025-03-18_14-33-21_0d7d2646\wandb\run-20250318_143345-sac_metadrive_2025-03-18_14-33-21_0d7d2646\logs\debug.log
2025-03-18 14:33:45,681 INFO    MainThread:22024 [wandb_init.py:setup_run_log_directory():648] Logging internal logs to runs\sac_metadrive\sac_metadrive_2025-03-18_14-33-21_0d7d2646\wandb\run-20250318_143345-sac_metadrive_2025-03-18_14-33-21_0d7d2646\logs\debug-internal.log
2025-03-18 14:33:45,681 INFO    MainThread:22024 [wandb_init.py:monkeypatch_ipython():599] configuring jupyter hooks <wandb.sdk.wandb_init._WandbInit object at 0x000002560E2FB490>
2025-03-18 14:33:45,686 INFO    MainThread:22024 [wandb_init.py:init():761] calling init triggers
2025-03-18 14:33:45,686 INFO    MainThread:22024 [wandb_init.py:init():766] wandb.init called with sweep_config: {}
config: {'_wandb': {}}
2025-03-18 14:33:45,686 INFO    MainThread:22024 [wandb_init.py:init():784] starting backend
2025-03-18 14:33:45,686 INFO    MainThread:22024 [wandb_init.py:init():788] sending inform_init request
2025-03-18 14:33:45,698 INFO    MainThread:22024 [backend.py:_multiprocessing_setup():101] multiprocessing start_methods=spawn, using: spawn
2025-03-18 14:33:45,698 INFO    MainThread:22024 [wandb_init.py:init():798] backend started and connected
2025-03-18 14:33:45,699 INFO    MainThread:22024 [wandb_run.py:_label_probe_notebook():1204] probe notebook
2025-03-18 14:33:45,710 INFO    MainThread:22024 [wandb_init.py:init():891] updated telemetry
2025-03-18 14:33:45,746 INFO    MainThread:22024 [wandb_init.py:init():915] communicating run to backend with 90.0 second timeout
2025-03-18 14:33:59,058 WARNING MsgRouterThr:22024 [router.py:message_loop():63] message_loop has been closed
Traceback (most recent call last):
  File "c:\Users\Colton\anaconda3\envs\cs260r\Lib\site-packages\wandb\sdk\lib\sock_client.py", line 208, in _read_packet_bytes
    data = self._sock.recv(self._bufsize)
           ^^^^^^^^^^^^^^^^^^^^^^^^^^^^^^
ConnectionResetError: [WinError 10054] An existing connection was forcibly closed by the remote host

The above exception was the direct cause of the following exception:

Traceback (most recent call last):
  File "c:\Users\Colton\anaconda3\envs\cs260r\Lib\site-packages\wandb\sdk\interface\router_sock.py", line 27, in _read_message
    return self._sock_client.read_server_response(timeout=1)
           ^^^^^^^^^^^^^^^^^^^^^^^^^^^^^^^^^^^^^^^^^^^^^^^^^
  File "c:\Users\Colton\anaconda3\envs\cs260r\Lib\site-packages\wandb\sdk\lib\sock_client.py", line 235, in read_server_response
    data = self._read_packet_bytes(timeout=timeout)
           ^^^^^^^^^^^^^^^^^^^^^^^^^^^^^^^^^^^^^^^^
  File "c:\Users\Colton\anaconda3\envs\cs260r\Lib\site-packages\wandb\sdk\lib\sock_client.py", line 212, in _read_packet_bytes
    raise SockClientClosedError from e
wandb.sdk.lib.sock_client.SockClientClosedError

The above exception was the direct cause of the following exception:

Traceback (most recent call last):
  File "c:\Users\Colton\anaconda3\envs\cs260r\Lib\site-packages\wandb\sdk\interface\router.py", line 56, in message_loop
    msg = self._read_message()
          ^^^^^^^^^^^^^^^^^^^^
  File "c:\Users\Colton\anaconda3\envs\cs260r\Lib\site-packages\wandb\sdk\interface\router_sock.py", line 29, in _read_message
    raise MessageRouterClosedError from e
wandb.sdk.interface.router.MessageRouterClosedError
2025-03-18 14:33:59,061 INFO    MsgRouterThr:22024 [mailbox.py:close():129] Closing mailbox, abandoning 1 handles.
2025-03-18 14:33:59,075 ERROR   MainThread:22024 [wandb_init.py:init():1478] error in wandb.init()
Traceback (most recent call last):
  File "c:\Users\Colton\anaconda3\envs\cs260r\Lib\site-packages\wandb\sdk\lib\asyncio_compat.py", line 205, in cancel_on_exit
    yield
  File "c:\Users\Colton\anaconda3\envs\cs260r\Lib\site-packages\wandb\sdk\mailbox\wait_with_progress.py", line 82, in progress_loop_with_timeout
    return await _wait_handles_async(
           ^^^^^^^^^^^^^^^^^^^^^^^^^^
  File "c:\Users\Colton\anaconda3\envs\cs260r\Lib\site-packages\wandb\sdk\mailbox\wait_with_progress.py", line 130, in _wait_handles_async
    async with asyncio_compat.open_task_group() as task_group:
  File "c:\Users\Colton\anaconda3\envs\cs260r\Lib\contextlib.py", line 217, in __aexit__
    await anext(self.gen)
  File "c:\Users\Colton\anaconda3\envs\cs260r\Lib\site-packages\wandb\sdk\lib\asyncio_compat.py", line 190, in open_task_group
    await task_group._wait_all()
  File "c:\Users\Colton\anaconda3\envs\cs260r\Lib\site-packages\wandb\sdk\lib\asyncio_compat.py", line 159, in _wait_all
    raise exc
  File "c:\Users\Colton\anaconda3\envs\cs260r\Lib\site-packages\wandb\sdk\mailbox\wait_with_progress.py", line 128, in wait_single
    results[index] = await handle.wait_async(timeout=timeout)
                     ^^^^^^^^^^^^^^^^^^^^^^^^^^^^^^^^^^^^^^^^
  File "c:\Users\Colton\anaconda3\envs\cs260r\Lib\site-packages\wandb\sdk\mailbox\mailbox_handle.py", line 126, in wait_async
    response = await self._handle.wait_async(timeout=timeout)
               ^^^^^^^^^^^^^^^^^^^^^^^^^^^^^^^^^^^^^^^^^^^^^^
  File "c:\Users\Colton\anaconda3\envs\cs260r\Lib\site-packages\wandb\sdk\mailbox\response_handle.py", line 128, in wait_async
    raise HandleAbandonedError()
wandb.sdk.mailbox.mailbox_handle.HandleAbandonedError

During handling of the above exception, another exception occurred:

Traceback (most recent call last):
  File "c:\Users\Colton\anaconda3\envs\cs260r\Lib\site-packages\wandb\sdk\wandb_init.py", line 1468, in init
    return wi.init(run_settings, run_config)
           ^^^^^^^^^^^^^^^^^^^^^^^^^^^^^^^^^
  File "c:\Users\Colton\anaconda3\envs\cs260r\Lib\site-packages\wandb\sdk\wandb_init.py", line 941, in init
    result = wait_with_progress(
             ^^^^^^^^^^^^^^^^^^^
  File "c:\Users\Colton\anaconda3\envs\cs260r\Lib\site-packages\wandb\sdk\mailbox\wait_with_progress.py", line 24, in wait_with_progress
    return wait_all_with_progress(
           ^^^^^^^^^^^^^^^^^^^^^^^
  File "c:\Users\Colton\anaconda3\envs\cs260r\Lib\site-packages\wandb\sdk\mailbox\wait_with_progress.py", line 87, in wait_all_with_progress
    return asyncio_compat.run(progress_loop_with_timeout)
           ^^^^^^^^^^^^^^^^^^^^^^^^^^^^^^^^^^^^^^^^^^^^^^
  File "c:\Users\Colton\anaconda3\envs\cs260r\Lib\site-packages\wandb\sdk\lib\asyncio_compat.py", line 30, in run
    return future.result()
           ^^^^^^^^^^^^^^^
  File "c:\Users\Colton\anaconda3\envs\cs260r\Lib\concurrent\futures\_base.py", line 456, in result
    return self.__get_result()
           ^^^^^^^^^^^^^^^^^^^
  File "c:\Users\Colton\anaconda3\envs\cs260r\Lib\concurrent\futures\_base.py", line 401, in __get_result
    raise self._exception
  File "c:\Users\Colton\anaconda3\envs\cs260r\Lib\concurrent\futures\thread.py", line 58, in run
    result = self.fn(*self.args, **self.kwargs)
             ^^^^^^^^^^^^^^^^^^^^^^^^^^^^^^^^^^
  File "c:\Users\Colton\anaconda3\envs\cs260r\Lib\site-packages\wandb\sdk\lib\asyncio_compat.py", line 74, in run
    return asyncio.run(self._run_or_cancel(fn))
           ^^^^^^^^^^^^^^^^^^^^^^^^^^^^^^^^^^^^
  File "c:\Users\Colton\anaconda3\envs\cs260r\Lib\asyncio\runners.py", line 190, in run
    return runner.run(main)
           ^^^^^^^^^^^^^^^^
  File "c:\Users\Colton\anaconda3\envs\cs260r\Lib\asyncio\runners.py", line 118, in run
    return self._loop.run_until_complete(task)
           ^^^^^^^^^^^^^^^^^^^^^^^^^^^^^^^^^^^
  File "c:\Users\Colton\anaconda3\envs\cs260r\Lib\asyncio\base_events.py", line 654, in run_until_complete
    return future.result()
           ^^^^^^^^^^^^^^^
  File "c:\Users\Colton\anaconda3\envs\cs260r\Lib\site-packages\wandb\sdk\lib\asyncio_compat.py", line 98, in _run_or_cancel
    return fn_task.result()
           ^^^^^^^^^^^^^^^^
  File "c:\Users\Colton\anaconda3\envs\cs260r\Lib\site-packages\wandb\sdk\mailbox\wait_with_progress.py", line 75, in progress_loop_with_timeout
    with asyncio_compat.cancel_on_exit(display_progress()):
  File "c:\Users\Colton\anaconda3\envs\cs260r\Lib\contextlib.py", line 158, in __exit__
    self.gen.throw(typ, value, traceback)
  File "c:\Users\Colton\anaconda3\envs\cs260r\Lib\site-packages\wandb\sdk\lib\asyncio_compat.py", line 208, in cancel_on_exit
    raise exception
  File "c:\Users\Colton\anaconda3\envs\cs260r\Lib\site-packages\wandb\sdk\wandb_init.py", line 928, in display_init_message
    await progress.loop_printing_operation_stats(
  File "c:\Users\Colton\anaconda3\envs\cs260r\Lib\site-packages\wandb\sdk\lib\progress.py", line 76, in loop_printing_operation_stats
    async with asyncio_compat.open_task_group() as task_group:
  File "c:\Users\Colton\anaconda3\envs\cs260r\Lib\contextlib.py", line 217, in __aexit__
    await anext(self.gen)
  File "c:\Users\Colton\anaconda3\envs\cs260r\Lib\site-packages\wandb\sdk\lib\asyncio_compat.py", line 190, in open_task_group
    await task_group._wait_all()
  File "c:\Users\Colton\anaconda3\envs\cs260r\Lib\site-packages\wandb\sdk\lib\asyncio_compat.py", line 159, in _wait_all
    raise exc
  File "c:\Users\Colton\anaconda3\envs\cs260r\Lib\site-packages\wandb\sdk\lib\progress.py", line 68, in loop_poll_stats
    handle = interface.deliver_operation_stats()
             ^^^^^^^^^^^^^^^^^^^^^^^^^^^^^^^^^^^
  File "c:\Users\Colton\anaconda3\envs\cs260r\Lib\site-packages\wandb\sdk\interface\interface_shared.py", line 440, in deliver_operation_stats
    return self._deliver_record(record)
           ^^^^^^^^^^^^^^^^^^^^^^^^^^^^
  File "c:\Users\Colton\anaconda3\envs\cs260r\Lib\site-packages\wandb\sdk\interface\interface_shared.py", line 389, in _deliver_record
    handle = mailbox.require_response(record)
             ^^^^^^^^^^^^^^^^^^^^^^^^^^^^^^^^
  File "c:\Users\Colton\anaconda3\envs\cs260r\Lib\site-packages\wandb\sdk\mailbox\mailbox.py", line 68, in require_response
    raise MailboxClosedError()
wandb.sdk.mailbox.mailbox.MailboxClosedError
